2021-11-29 10:38:10,911 [ERROR] root: Traceback (most recent call last):
  File "C:\Users\DRL-Team\Desktop\DMP APP FOR PRO\venv\lib\site-packages\pandas\core\indexes\base.py", line 3361, in get_loc
    return self._engine.get_loc(casted_key)
  File "pandas\_libs\index.pyx", line 76, in pandas._libs.index.IndexEngine.get_loc
  File "pandas\_libs\index.pyx", line 108, in pandas._libs.index.IndexEngine.get_loc
  File "pandas\_libs\hashtable_class_helper.pxi", line 5198, in pandas._libs.hashtable.PyObjectHashTable.get_item
  File "pandas\_libs\hashtable_class_helper.pxi", line 5206, in pandas._libs.hashtable.PyObjectHashTable.get_item
KeyError: 'Unit Price'

The above exception was the direct cause of the following exception:

Traceback (most recent call last):
  File "C:\Users\DRL-Team\Desktop\DMP APP FOR PRO\DMP_API\DMP_APP\views_visual_1.py", line 141, in searching
    all_dataframes_from_searching = main_searching_algoritm(DMP.input_material_id, DMP.input_description, DMP.input_manufacturer_part_number, DMP.input_manufacturer_name, processed_df)
  File "C:\Users\DRL-Team\Desktop\DMP APP FOR PRO\DMP_API\DMP_APP\views_search_1.py", line 384, in main_searching_algoritm
    app = normalize(app)
  File "C:\Users\DRL-Team\Desktop\DMP APP FOR PRO\DMP_API\DMP_APP\helpers.py", line 531, in normalize
    in_data['Converted Price'] = in_data['Unit Price']
  File "C:\Users\DRL-Team\Desktop\DMP APP FOR PRO\venv\lib\site-packages\pandas\core\frame.py", line 3458, in __getitem__
    indexer = self.columns.get_loc(key)
  File "C:\Users\DRL-Team\Desktop\DMP APP FOR PRO\venv\lib\site-packages\pandas\core\indexes\base.py", line 3363, in get_loc
    raise KeyError(key) from err
KeyError: 'Unit Price'