2021-12-07 16:34:49,037 [ERROR] django.request: HTTP Version Not Supported: /home/check_user_status/
2021-12-07 16:34:55,737 [ERROR] django.request: HTTP Version Not Supported: /home/check_user_status/
2021-12-07 16:35:07,271 [ERROR] django.request: HTTP Version Not Supported: /home/check_user_status/
2021-12-07 16:44:51,308 [ERROR] django.request: HTTP Version Not Supported: /home/check_user_status/
2021-12-07 16:44:53,956 [ERROR] django.request: HTTP Version Not Supported: /home/check_user_status/
2021-12-07 16:44:57,494 [ERROR] django.request: HTTP Version Not Supported: /home/check_user_status/
2021-12-07 16:46:12,861 [ERROR] django.request: HTTP Version Not Supported: /home/check_user_status/
2021-12-07 16:47:49,500 [ERROR] django.request: HTTP Version Not Supported: /home/check_user_status/
2021-12-07 16:48:26,189 [ERROR] django.request: HTTP Version Not Supported: /home/check_user_status/
2021-12-07 16:48:28,953 [ERROR] django.request: HTTP Version Not Supported: /home/check_user_status/
2021-12-07 16:49:29,408 [ERROR] django.request: HTTP Version Not Supported: /home/check_user_status/
2021-12-07 16:51:34,385 [ERROR] django.request: HTTP Version Not Supported: /home/check_user_status/
2021-12-08 01:20:26,241 [ERROR] django.request: HTTP Version Not Supported: /home/check_user_status/
2021-12-08 01:20:30,813 [ERROR] django.request: HTTP Version Not Supported: /home/check_user_status/
2021-12-08 12:00:39,056 [ERROR] django.request: Internal Server Error: /home/login/
Traceback (most recent call last):
  File "C:\Users\DRL-Team\Desktop\DMP\DMPVenv\lib\site-packages\sqlalchemy\engine\base.py", line 1803, in _execute_context
    cursor, statement, parameters, context
  File "C:\Users\DRL-Team\Desktop\DMP\DMPVenv\lib\site-packages\sqlalchemy\engine\default.py", line 719, in do_execute
    cursor.execute(statement, parameters)
psycopg2.OperationalError: server closed the connection unexpectedly
	This probably means the server terminated abnormally
	before or while processing the request.
server closed the connection unexpectedly
	This probably means the server terminated abnormally
	before or while processing the request.


The above exception was the direct cause of the following exception:

Traceback (most recent call last):
  File "C:\Users\DRL-Team\Desktop\DMP\DMPVenv\lib\site-packages\django\core\handlers\exception.py", line 47, in inner
    response = get_response(request)
  File "C:\Users\DRL-Team\Desktop\DMP\DMPVenv\lib\site-packages\django\core\handlers\base.py", line 181, in _get_response
    response = wrapped_callback(request, *callback_args, **callback_kwargs)
  File "C:\Users\DRL-Team\Desktop\DMP\DMPVenv\lib\site-packages\django\views\decorators\csrf.py", line 54, in wrapped_view
    return view_func(*args, **kwargs)
  File "C:\Users\DRL-Team\Desktop\DMP\DMP_2\DMP_API\DMP_APP\custom_logic.py", line 109, in login
    sql_table = serializer(sql_table)
  File "C:\Users\DRL-Team\Desktop\DMP\DMP_2\DMP_API\DMP_APP\custom_logic.py", line 231, in serializer
    return [dict(row) for row in rows]
  File "C:\Users\DRL-Team\Desktop\DMP\DMPVenv\lib\site-packages\sqlalchemy\orm\query.py", line 2887, in __iter__
    return self._iter().__iter__()
  File "C:\Users\DRL-Team\Desktop\DMP\DMPVenv\lib\site-packages\sqlalchemy\orm\query.py", line 2897, in _iter
    execution_options={"_sa_orm_load_options": self.load_options},
  File "C:\Users\DRL-Team\Desktop\DMP\DMPVenv\lib\site-packages\sqlalchemy\orm\session.py", line 1689, in execute
    result = conn._execute_20(statement, params or {}, execution_options)
  File "C:\Users\DRL-Team\Desktop\DMP\DMPVenv\lib\site-packages\sqlalchemy\engine\base.py", line 1614, in _execute_20
    return meth(self, args_10style, kwargs_10style, execution_options)
  File "C:\Users\DRL-Team\Desktop\DMP\DMPVenv\lib\site-packages\sqlalchemy\sql\elements.py", line 326, in _execute_on_connection
    self, multiparams, params, execution_options
  File "C:\Users\DRL-Team\Desktop\DMP\DMPVenv\lib\site-packages\sqlalchemy\engine\base.py", line 1491, in _execute_clauseelement
    cache_hit=cache_hit,
  File "C:\Users\DRL-Team\Desktop\DMP\DMPVenv\lib\site-packages\sqlalchemy\engine\base.py", line 1846, in _execute_context
    e, statement, parameters, cursor, context
  File "C:\Users\DRL-Team\Desktop\DMP\DMPVenv\lib\site-packages\sqlalchemy\engine\base.py", line 2027, in _handle_dbapi_exception
    sqlalchemy_exception, with_traceback=exc_info[2], from_=e
  File "C:\Users\DRL-Team\Desktop\DMP\DMPVenv\lib\site-packages\sqlalchemy\util\compat.py", line 207, in raise_
    raise exception
  File "C:\Users\DRL-Team\Desktop\DMP\DMPVenv\lib\site-packages\sqlalchemy\engine\base.py", line 1803, in _execute_context
    cursor, statement, parameters, context
  File "C:\Users\DRL-Team\Desktop\DMP\DMPVenv\lib\site-packages\sqlalchemy\engine\default.py", line 719, in do_execute
    cursor.execute(statement, parameters)
sqlalchemy.exc.OperationalError: (psycopg2.OperationalError) server closed the connection unexpectedly
	This probably means the server terminated abnormally
	before or while processing the request.
server closed the connection unexpectedly
	This probably means the server terminated abnormally
	before or while processing the request.

[SQL: SELECT dmp_users.user_name AS dmp_users_user_name, dmp_users.user_mail AS dmp_users_user_mail, dmp_users.first_name AS dmp_users_first_name, dmp_users.last_name AS dmp_users_last_name, dmp_users.user_password AS dmp_users_user_password, dmp_users.user_type AS dmp_users_user_type, dmp_users.user_id AS dmp_users_user_id, user_session.user_token AS user_session_user_token 
FROM dmp_users JOIN user_session ON user_session.user_id = dmp_users.user_id 
WHERE dmp_users.user_name = %(user_name_1)s ORDER BY dmp_users.user_name]
[parameters: {'user_name_1': 'Farid612'}]
(Background on this error at: https://sqlalche.me/e/14/e3q8)
2021-12-08 12:09:59,427 [ERROR] django.request: HTTP Version Not Supported: /home/check_user_status/
2021-12-08 12:10:06,295 [ERROR] django.request: HTTP Version Not Supported: /home/check_user_status/
2021-12-08 12:11:07,768 [ERROR] django.request: HTTP Version Not Supported: /home/check_user_status/
2021-12-08 12:45:22,742 [ERROR] django.request: HTTP Version Not Supported: /home/upload_sql_table/
2021-12-08 13:06:02,557 [ERROR] django.request: HTTP Version Not Supported: /home/upload_sql_table/
2021-12-08 13:16:28,918 [ERROR] django.request: Internal Server Error: /home/upload_sql_table/
Traceback (most recent call last):
  File "C:\Users\DRL-Team\Desktop\DMP\DMPVenv\lib\site-packages\sqlalchemy\engine\base.py", line 1803, in _execute_context
    cursor, statement, parameters, context
  File "C:\Users\DRL-Team\Desktop\DMP\DMPVenv\lib\site-packages\sqlalchemy\engine\default.py", line 719, in do_execute
    cursor.execute(statement, parameters)
psycopg2.errors.SyntaxError: syntax error at or near "INTEGER"
LINE 1: ALTER TABLE Customer alter column customer_id INTEGER PRIMAR...
                                                      ^


The above exception was the direct cause of the following exception:

Traceback (most recent call last):
  File "C:\Users\DRL-Team\Desktop\DMP\DMPVenv\lib\site-packages\django\core\handlers\exception.py", line 47, in inner
    response = get_response(request)
  File "C:\Users\DRL-Team\Desktop\DMP\DMPVenv\lib\site-packages\django\core\handlers\base.py", line 181, in _get_response
    response = wrapped_callback(request, *callback_args, **callback_kwargs)
  File "C:\Users\DRL-Team\Desktop\DMP\DMPVenv\lib\site-packages\django\views\decorators\csrf.py", line 54, in wrapped_view
    return view_func(*args, **kwargs)
  File "C:\Users\DRL-Team\Desktop\DMP\DMP_2\DMP_API\DMP_APP\custom_logic.py", line 106, in upload_sql_table
    con.execute(query_1)
  File "C:\Users\DRL-Team\Desktop\DMP\DMPVenv\lib\site-packages\sqlalchemy\engine\base.py", line 1279, in execute
    future=False,
  File "C:\Users\DRL-Team\Desktop\DMP\DMPVenv\lib\site-packages\sqlalchemy\engine\base.py", line 1585, in _exec_driver_sql
    distilled_parameters,
  File "C:\Users\DRL-Team\Desktop\DMP\DMPVenv\lib\site-packages\sqlalchemy\engine\base.py", line 1846, in _execute_context
    e, statement, parameters, cursor, context
  File "C:\Users\DRL-Team\Desktop\DMP\DMPVenv\lib\site-packages\sqlalchemy\engine\base.py", line 2027, in _handle_dbapi_exception
    sqlalchemy_exception, with_traceback=exc_info[2], from_=e
  File "C:\Users\DRL-Team\Desktop\DMP\DMPVenv\lib\site-packages\sqlalchemy\util\compat.py", line 207, in raise_
    raise exception
  File "C:\Users\DRL-Team\Desktop\DMP\DMPVenv\lib\site-packages\sqlalchemy\engine\base.py", line 1803, in _execute_context
    cursor, statement, parameters, context
  File "C:\Users\DRL-Team\Desktop\DMP\DMPVenv\lib\site-packages\sqlalchemy\engine\default.py", line 719, in do_execute
    cursor.execute(statement, parameters)
sqlalchemy.exc.ProgrammingError: (psycopg2.errors.SyntaxError) syntax error at or near "INTEGER"
LINE 1: ALTER TABLE Customer alter column customer_id INTEGER PRIMAR...
                                                      ^

[SQL: ALTER TABLE Customer alter column customer_id INTEGER PRIMARY KEY]
(Background on this error at: https://sqlalche.me/e/14/f405)
2021-12-08 13:27:47,449 [ERROR] django.request: Internal Server Error: /home/upload_sql_table/
Traceback (most recent call last):
  File "C:\Users\DRL-Team\Desktop\DMP\DMPVenv\lib\site-packages\sqlalchemy\engine\base.py", line 1803, in _execute_context
    cursor, statement, parameters, context
  File "C:\Users\DRL-Team\Desktop\DMP\DMPVenv\lib\site-packages\sqlalchemy\engine\default.py", line 719, in do_execute
    cursor.execute(statement, parameters)
psycopg2.errors.SyntaxError: syntax error at or near "INTEGER"
LINE 1: ALTER TABLE Customer alter column customer_id INTEGER PRIMAR...
                                                      ^


The above exception was the direct cause of the following exception:

Traceback (most recent call last):
  File "C:\Users\DRL-Team\Desktop\DMP\DMPVenv\lib\site-packages\django\core\handlers\exception.py", line 47, in inner
    response = get_response(request)
  File "C:\Users\DRL-Team\Desktop\DMP\DMPVenv\lib\site-packages\django\core\handlers\base.py", line 181, in _get_response
    response = wrapped_callback(request, *callback_args, **callback_kwargs)
  File "C:\Users\DRL-Team\Desktop\DMP\DMPVenv\lib\site-packages\django\views\decorators\csrf.py", line 54, in wrapped_view
    return view_func(*args, **kwargs)
  File "C:\Users\DRL-Team\Desktop\DMP\DMP_2\DMP_API\DMP_APP\custom_logic.py", line 105, in upload_sql_table
    con.execute(query_1)
  File "C:\Users\DRL-Team\Desktop\DMP\DMPVenv\lib\site-packages\sqlalchemy\engine\base.py", line 1279, in execute
    future=False,
  File "C:\Users\DRL-Team\Desktop\DMP\DMPVenv\lib\site-packages\sqlalchemy\engine\base.py", line 1585, in _exec_driver_sql
    distilled_parameters,
  File "C:\Users\DRL-Team\Desktop\DMP\DMPVenv\lib\site-packages\sqlalchemy\engine\base.py", line 1846, in _execute_context
    e, statement, parameters, cursor, context
  File "C:\Users\DRL-Team\Desktop\DMP\DMPVenv\lib\site-packages\sqlalchemy\engine\base.py", line 2027, in _handle_dbapi_exception
    sqlalchemy_exception, with_traceback=exc_info[2], from_=e
  File "C:\Users\DRL-Team\Desktop\DMP\DMPVenv\lib\site-packages\sqlalchemy\util\compat.py", line 207, in raise_
    raise exception
  File "C:\Users\DRL-Team\Desktop\DMP\DMPVenv\lib\site-packages\sqlalchemy\engine\base.py", line 1803, in _execute_context
    cursor, statement, parameters, context
  File "C:\Users\DRL-Team\Desktop\DMP\DMPVenv\lib\site-packages\sqlalchemy\engine\default.py", line 719, in do_execute
    cursor.execute(statement, parameters)
sqlalchemy.exc.ProgrammingError: (psycopg2.errors.SyntaxError) syntax error at or near "INTEGER"
LINE 1: ALTER TABLE Customer alter column customer_id INTEGER PRIMAR...
                                                      ^

[SQL: ALTER TABLE Customer alter column customer_id INTEGER PRIMARY KEY]
(Background on this error at: https://sqlalche.me/e/14/f405)
2021-12-08 13:29:16,932 [ERROR] django.request: Internal Server Error: /home/upload_sql_table/
Traceback (most recent call last):
  File "C:\Users\DRL-Team\Desktop\DMP\DMPVenv\lib\site-packages\sqlalchemy\engine\base.py", line 1803, in _execute_context
    cursor, statement, parameters, context
  File "C:\Users\DRL-Team\Desktop\DMP\DMPVenv\lib\site-packages\sqlalchemy\engine\default.py", line 719, in do_execute
    cursor.execute(statement, parameters)
psycopg2.errors.SyntaxError: syntax error at or near "INTEGER"
LINE 1: ALTER TABLE Customer alter column customer_id INTEGER PRIMAR...
                                                      ^


The above exception was the direct cause of the following exception:

Traceback (most recent call last):
  File "C:\Users\DRL-Team\Desktop\DMP\DMPVenv\lib\site-packages\django\core\handlers\exception.py", line 47, in inner
    response = get_response(request)
  File "C:\Users\DRL-Team\Desktop\DMP\DMPVenv\lib\site-packages\django\core\handlers\base.py", line 181, in _get_response
    response = wrapped_callback(request, *callback_args, **callback_kwargs)
  File "C:\Users\DRL-Team\Desktop\DMP\DMPVenv\lib\site-packages\django\views\decorators\csrf.py", line 54, in wrapped_view
    return view_func(*args, **kwargs)
  File "C:\Users\DRL-Team\Desktop\DMP\DMP_2\DMP_API\DMP_APP\custom_logic.py", line 106, in upload_sql_table
    con.execute(query_1)
  File "C:\Users\DRL-Team\Desktop\DMP\DMPVenv\lib\site-packages\sqlalchemy\engine\base.py", line 1279, in execute
    future=False,
  File "C:\Users\DRL-Team\Desktop\DMP\DMPVenv\lib\site-packages\sqlalchemy\engine\base.py", line 1585, in _exec_driver_sql
    distilled_parameters,
  File "C:\Users\DRL-Team\Desktop\DMP\DMPVenv\lib\site-packages\sqlalchemy\engine\base.py", line 1846, in _execute_context
    e, statement, parameters, cursor, context
  File "C:\Users\DRL-Team\Desktop\DMP\DMPVenv\lib\site-packages\sqlalchemy\engine\base.py", line 2027, in _handle_dbapi_exception
    sqlalchemy_exception, with_traceback=exc_info[2], from_=e
  File "C:\Users\DRL-Team\Desktop\DMP\DMPVenv\lib\site-packages\sqlalchemy\util\compat.py", line 207, in raise_
    raise exception
  File "C:\Users\DRL-Team\Desktop\DMP\DMPVenv\lib\site-packages\sqlalchemy\engine\base.py", line 1803, in _execute_context
    cursor, statement, parameters, context
  File "C:\Users\DRL-Team\Desktop\DMP\DMPVenv\lib\site-packages\sqlalchemy\engine\default.py", line 719, in do_execute
    cursor.execute(statement, parameters)
sqlalchemy.exc.ProgrammingError: (psycopg2.errors.SyntaxError) syntax error at or near "INTEGER"
LINE 1: ALTER TABLE Customer alter column customer_id INTEGER PRIMAR...
                                                      ^

[SQL: ALTER TABLE Customer alter column customer_id INTEGER PRIMARY KEY]
(Background on this error at: https://sqlalche.me/e/14/f405)
2021-12-08 14:40:23,586 [ERROR] django.request: HTTP Version Not Supported: /home/upload_sql_table/
2021-12-08 15:06:04,802 [ERROR] django.request: HTTP Version Not Supported: /home/check_user_status/
2021-12-08 15:54:05,442 [ERROR] django.request: HTTP Version Not Supported: /home/upload_sql_table/
2021-12-08 15:54:11,238 [ERROR] django.request: HTTP Version Not Supported: /home/upload_sql_table/
2021-12-08 16:19:00,023 [ERROR] django.request: HTTP Version Not Supported: /home/check_user_status/
2021-12-08 16:20:11,336 [ERROR] django.request: HTTP Version Not Supported: /home/check_user_status/
2021-12-08 16:21:47,985 [ERROR] django.request: HTTP Version Not Supported: /home/check_user_status/
2021-12-08 16:22:21,539 [ERROR] django.request: HTTP Version Not Supported: /home/check_user_status/
2021-12-08 16:22:23,293 [ERROR] django.request: HTTP Version Not Supported: /home/check_user_status/
2021-12-08 16:22:44,261 [ERROR] django.request: HTTP Version Not Supported: /home/check_user_status/
2021-12-08 16:24:00,206 [ERROR] django.request: HTTP Version Not Supported: /home/check_user_status/
2021-12-08 16:24:57,145 [ERROR] django.request: HTTP Version Not Supported: /home/check_user_status/
2021-12-08 21:24:42,427 [ERROR] django.request: HTTP Version Not Supported: /home/check_user_status/
2021-12-08 21:25:57,027 [ERROR] django.request: HTTP Version Not Supported: /home/check_user_status/
2021-12-08 21:26:18,354 [ERROR] django.request: HTTP Version Not Supported: /home/check_user_status/
2021-12-08 22:11:38,656 [ERROR] django.request: HTTP Version Not Supported: /pricebook/get_all_customer/
2021-12-08 23:45:07,444 [ERROR] django.request: HTTP Version Not Supported: /pricebook/get_all_customer/
2021-12-08 23:51:16,269 [ERROR] django.request: HTTP Version Not Supported: /pricebook/get_all_customer/
2021-12-09 14:27:00,511 [ERROR] django.request: HTTP Version Not Supported: /home/check_user_status/
2021-12-09 14:27:07,769 [ERROR] django.request: HTTP Version Not Supported: /home/check_user_status/
2021-12-09 14:27:46,718 [ERROR] django.request: HTTP Version Not Supported: /home/check_user_status/
2021-12-09 14:27:57,635 [ERROR] django.request: HTTP Version Not Supported: /home/check_user_status/
2021-12-09 14:28:34,201 [ERROR] django.request: HTTP Version Not Supported: /home/check_user_status/
2021-12-09 17:04:21,590 [ERROR] django.request: HTTP Version Not Supported: /home/check_user_status/
2021-12-09 17:04:21,610 [ERROR] django.request: Not Implemented: /pricebook/get_all_customer/
2021-12-09 17:04:31,691 [ERROR] django.request: Not Implemented: /pricebook/get_all_customer/
2021-12-09 17:06:11,934 [ERROR] django.request: HTTP Version Not Supported: /pricebook/pricebook_table/
2021-12-09 17:08:50,926 [ERROR] django.request: Not Implemented: /rfp/get_discount/
2021-12-09 17:08:57,359 [ERROR] django.request: HTTP Version Not Supported: /home/check_user_status/
2021-12-09 17:09:05,478 [ERROR] django.request: HTTP Version Not Supported: /rfp/get_discount/
2021-12-09 17:09:19,409 [ERROR] django.request: HTTP Version Not Supported: /rfp/get_discount/
2021-12-09 17:09:35,563 [ERROR] django.request: HTTP Version Not Supported: /rfp/get_discount/
2021-12-09 17:09:39,661 [ERROR] django.request: HTTP Version Not Supported: /rfp/get_discount/
2021-12-09 17:10:03,729 [ERROR] django.request: HTTP Version Not Supported: /home/check_user_status/
2021-12-09 17:10:09,376 [ERROR] django.request: HTTP Version Not Supported: /home/check_user_status/
2021-12-09 17:27:42,701 [ERROR] django.request: HTTP Version Not Supported: /pricebook/pricebook_table/
2021-12-10 14:03:28,276 [ERROR] django.request: HTTP Version Not Supported: /home/check_user_status/
2021-12-10 17:10:09,926 [ERROR] django.request: HTTP Version Not Supported: /home/check_user_status/
2021-12-10 17:10:09,957 [ERROR] django.request: Not Implemented: /pricebook/get_all_customer/
